Watching for file changes with StatReloader
/Users/vaibhavsingh/Desktop/ASMP25-26/Backend/Authentication/models.py changed, reloading.
Watching for file changes with StatReloader
Watching for file changes with StatReloader
Not Found: /api/authentication/profile/
Not Found: /api/authentication/profile/
Internal Server Error: /api/registration/wishlist/
Traceback (most recent call last):
  File "/Users/vaibhavsingh/Desktop/ASMP25-26/Backend/venv/lib/python3.13/site-packages/django/db/backends/utils.py", line 105, in _execute
    return self.cursor.execute(sql, params)
           ~~~~~~~~~~~~~~~~~~~^^^^^^^^^^^^^
  File "/Users/vaibhavsingh/Desktop/ASMP25-26/Backend/venv/lib/python3.13/site-packages/django/db/backends/sqlite3/base.py", line 360, in execute
    return super().execute(query, params)
           ~~~~~~~~~~~~~~~^^^^^^^^^^^^^^^
sqlite3.OperationalError: no such column: Authentication_user.reminder_sent

The above exception was the direct cause of the following exception:

Traceback (most recent call last):
  File "/Users/vaibhavsingh/Desktop/ASMP25-26/Backend/venv/lib/python3.13/site-packages/django/core/handlers/exception.py", line 55, in inner
    response = get_response(request)
  File "/Users/vaibhavsingh/Desktop/ASMP25-26/Backend/venv/lib/python3.13/site-packages/django/core/handlers/base.py", line 197, in _get_response
    response = wrapped_callback(request, *callback_args, **callback_kwargs)
  File "/Users/vaibhavsingh/Desktop/ASMP25-26/Backend/venv/lib/python3.13/site-packages/django/views/decorators/csrf.py", line 65, in _view_wrapper
    return view_func(request, *args, **kwargs)
  File "/Users/vaibhavsingh/Desktop/ASMP25-26/Backend/venv/lib/python3.13/site-packages/django/views/generic/base.py", line 105, in view
    return self.dispatch(request, *args, **kwargs)
           ~~~~~~~~~~~~~^^^^^^^^^^^^^^^^^^^^^^^^^^
  File "/Users/vaibhavsingh/Desktop/ASMP25-26/Backend/venv/lib/python3.13/site-packages/rest_framework/views.py", line 515, in dispatch
    response = self.handle_exception(exc)
  File "/Users/vaibhavsingh/Desktop/ASMP25-26/Backend/venv/lib/python3.13/site-packages/rest_framework/views.py", line 475, in handle_exception
    self.raise_uncaught_exception(exc)
    ~~~~~~~~~~~~~~~~~~~~~~~~~~~~~^^^^^
  File "/Users/vaibhavsingh/Desktop/ASMP25-26/Backend/venv/lib/python3.13/site-packages/rest_framework/views.py", line 486, in raise_uncaught_exception
    raise exc
  File "/Users/vaibhavsingh/Desktop/ASMP25-26/Backend/venv/lib/python3.13/site-packages/rest_framework/views.py", line 512, in dispatch
    response = handler(request, *args, **kwargs)
  File "/Users/vaibhavsingh/Desktop/ASMP25-26/Backend/Registrations/views.py", line 184, in get
    user = User.objects.get(accessToken=accessToken)
  File "/Users/vaibhavsingh/Desktop/ASMP25-26/Backend/venv/lib/python3.13/site-packages/django/db/models/manager.py", line 87, in manager_method
    return getattr(self.get_queryset(), name)(*args, **kwargs)
           ~~~~~~~~~~~~~~~~~~~~~~~~~~~~~~~~~~^^^^^^^^^^^^^^^^^
  File "/Users/vaibhavsingh/Desktop/ASMP25-26/Backend/venv/lib/python3.13/site-packages/django/db/models/query.py", line 629, in get
    num = len(clone)
  File "/Users/vaibhavsingh/Desktop/ASMP25-26/Backend/venv/lib/python3.13/site-packages/django/db/models/query.py", line 366, in __len__
    self._fetch_all()
    ~~~~~~~~~~~~~~~^^
  File "/Users/vaibhavsingh/Desktop/ASMP25-26/Backend/venv/lib/python3.13/site-packages/django/db/models/query.py", line 1949, in _fetch_all
    self._result_cache = list(self._iterable_class(self))
                         ~~~~^^^^^^^^^^^^^^^^^^^^^^^^^^^^
  File "/Users/vaibhavsingh/Desktop/ASMP25-26/Backend/venv/lib/python3.13/site-packages/django/db/models/query.py", line 91, in __iter__
    results = compiler.execute_sql(
        chunked_fetch=self.chunked_fetch, chunk_size=self.chunk_size
    )
  File "/Users/vaibhavsingh/Desktop/ASMP25-26/Backend/venv/lib/python3.13/site-packages/django/db/models/sql/compiler.py", line 1623, in execute_sql
    cursor.execute(sql, params)
    ~~~~~~~~~~~~~~^^^^^^^^^^^^^
  File "/Users/vaibhavsingh/Desktop/ASMP25-26/Backend/venv/lib/python3.13/site-packages/django/db/backends/utils.py", line 122, in execute
    return super().execute(sql, params)
           ~~~~~~~~~~~~~~~^^^^^^^^^^^^^
  File "/Users/vaibhavsingh/Desktop/ASMP25-26/Backend/venv/lib/python3.13/site-packages/django/db/backends/utils.py", line 79, in execute
    return self._execute_with_wrappers(
           ~~~~~~~~~~~~~~~~~~~~~~~~~~~^
        sql, params, many=False, executor=self._execute
        ^^^^^^^^^^^^^^^^^^^^^^^^^^^^^^^^^^^^^^^^^^^^^^^
    )
    ^
  File "/Users/vaibhavsingh/Desktop/ASMP25-26/Backend/venv/lib/python3.13/site-packages/django/db/backends/utils.py", line 92, in _execute_with_wrappers
    return executor(sql, params, many, context)
  File "/Users/vaibhavsingh/Desktop/ASMP25-26/Backend/venv/lib/python3.13/site-packages/django/db/backends/utils.py", line 100, in _execute
    with self.db.wrap_database_errors:
         ^^^^^^^^^^^^^^^^^^^^^^^^^^^^
  File "/Users/vaibhavsingh/Desktop/ASMP25-26/Backend/venv/lib/python3.13/site-packages/django/db/utils.py", line 91, in __exit__
    raise dj_exc_value.with_traceback(traceback) from exc_value
  File "/Users/vaibhavsingh/Desktop/ASMP25-26/Backend/venv/lib/python3.13/site-packages/django/db/backends/utils.py", line 105, in _execute
    return self.cursor.execute(sql, params)
           ~~~~~~~~~~~~~~~~~~~^^^^^^^^^^^^^
  File "/Users/vaibhavsingh/Desktop/ASMP25-26/Backend/venv/lib/python3.13/site-packages/django/db/backends/sqlite3/base.py", line 360, in execute
    return super().execute(query, params)
           ~~~~~~~~~~~~~~~^^^^^^^^^^^^^^^
django.db.utils.OperationalError: no such column: Authentication_user.reminder_sent
Internal Server Error: /api/registration/wishlist/
Traceback (most recent call last):
  File "/Users/vaibhavsingh/Desktop/ASMP25-26/Backend/venv/lib/python3.13/site-packages/django/db/backends/utils.py", line 105, in _execute
    return self.cursor.execute(sql, params)
           ~~~~~~~~~~~~~~~~~~~^^^^^^^^^^^^^
  File "/Users/vaibhavsingh/Desktop/ASMP25-26/Backend/venv/lib/python3.13/site-packages/django/db/backends/sqlite3/base.py", line 360, in execute
    return super().execute(query, params)
           ~~~~~~~~~~~~~~~^^^^^^^^^^^^^^^
sqlite3.OperationalError: no such column: Authentication_user.reminder_sent

The above exception was the direct cause of the following exception:

Traceback (most recent call last):
  File "/Users/vaibhavsingh/Desktop/ASMP25-26/Backend/venv/lib/python3.13/site-packages/django/core/handlers/exception.py", line 55, in inner
    response = get_response(request)
  File "/Users/vaibhavsingh/Desktop/ASMP25-26/Backend/venv/lib/python3.13/site-packages/django/core/handlers/base.py", line 197, in _get_response
    response = wrapped_callback(request, *callback_args, **callback_kwargs)
  File "/Users/vaibhavsingh/Desktop/ASMP25-26/Backend/venv/lib/python3.13/site-packages/django/views/decorators/csrf.py", line 65, in _view_wrapper
    return view_func(request, *args, **kwargs)
  File "/Users/vaibhavsingh/Desktop/ASMP25-26/Backend/venv/lib/python3.13/site-packages/django/views/generic/base.py", line 105, in view
    return self.dispatch(request, *args, **kwargs)
           ~~~~~~~~~~~~~^^^^^^^^^^^^^^^^^^^^^^^^^^
  File "/Users/vaibhavsingh/Desktop/ASMP25-26/Backend/venv/lib/python3.13/site-packages/rest_framework/views.py", line 515, in dispatch
    response = self.handle_exception(exc)
  File "/Users/vaibhavsingh/Desktop/ASMP25-26/Backend/venv/lib/python3.13/site-packages/rest_framework/views.py", line 475, in handle_exception
    self.raise_uncaught_exception(exc)
    ~~~~~~~~~~~~~~~~~~~~~~~~~~~~~^^^^^
  File "/Users/vaibhavsingh/Desktop/ASMP25-26/Backend/venv/lib/python3.13/site-packages/rest_framework/views.py", line 486, in raise_uncaught_exception
    raise exc
  File "/Users/vaibhavsingh/Desktop/ASMP25-26/Backend/venv/lib/python3.13/site-packages/rest_framework/views.py", line 512, in dispatch
    response = handler(request, *args, **kwargs)
  File "/Users/vaibhavsingh/Desktop/ASMP25-26/Backend/Registrations/views.py", line 184, in get
    user = User.objects.get(accessToken=accessToken)
  File "/Users/vaibhavsingh/Desktop/ASMP25-26/Backend/venv/lib/python3.13/site-packages/django/db/models/manager.py", line 87, in manager_method
    return getattr(self.get_queryset(), name)(*args, **kwargs)
           ~~~~~~~~~~~~~~~~~~~~~~~~~~~~~~~~~~^^^^^^^^^^^^^^^^^
  File "/Users/vaibhavsingh/Desktop/ASMP25-26/Backend/venv/lib/python3.13/site-packages/django/db/models/query.py", line 629, in get
    num = len(clone)
  File "/Users/vaibhavsingh/Desktop/ASMP25-26/Backend/venv/lib/python3.13/site-packages/django/db/models/query.py", line 366, in __len__
    self._fetch_all()
    ~~~~~~~~~~~~~~~^^
  File "/Users/vaibhavsingh/Desktop/ASMP25-26/Backend/venv/lib/python3.13/site-packages/django/db/models/query.py", line 1949, in _fetch_all
    self._result_cache = list(self._iterable_class(self))
                         ~~~~^^^^^^^^^^^^^^^^^^^^^^^^^^^^
  File "/Users/vaibhavsingh/Desktop/ASMP25-26/Backend/venv/lib/python3.13/site-packages/django/db/models/query.py", line 91, in __iter__
    results = compiler.execute_sql(
        chunked_fetch=self.chunked_fetch, chunk_size=self.chunk_size
    )
  File "/Users/vaibhavsingh/Desktop/ASMP25-26/Backend/venv/lib/python3.13/site-packages/django/db/models/sql/compiler.py", line 1623, in execute_sql
    cursor.execute(sql, params)
    ~~~~~~~~~~~~~~^^^^^^^^^^^^^
  File "/Users/vaibhavsingh/Desktop/ASMP25-26/Backend/venv/lib/python3.13/site-packages/django/db/backends/utils.py", line 122, in execute
    return super().execute(sql, params)
           ~~~~~~~~~~~~~~~^^^^^^^^^^^^^
  File "/Users/vaibhavsingh/Desktop/ASMP25-26/Backend/venv/lib/python3.13/site-packages/django/db/backends/utils.py", line 79, in execute
    return self._execute_with_wrappers(
           ~~~~~~~~~~~~~~~~~~~~~~~~~~~^
        sql, params, many=False, executor=self._execute
        ^^^^^^^^^^^^^^^^^^^^^^^^^^^^^^^^^^^^^^^^^^^^^^^
    )
    ^
  File "/Users/vaibhavsingh/Desktop/ASMP25-26/Backend/venv/lib/python3.13/site-packages/django/db/backends/utils.py", line 92, in _execute_with_wrappers
    return executor(sql, params, many, context)
  File "/Users/vaibhavsingh/Desktop/ASMP25-26/Backend/venv/lib/python3.13/site-packages/django/db/backends/utils.py", line 100, in _execute
    with self.db.wrap_database_errors:
         ^^^^^^^^^^^^^^^^^^^^^^^^^^^^
  File "/Users/vaibhavsingh/Desktop/ASMP25-26/Backend/venv/lib/python3.13/site-packages/django/db/utils.py", line 91, in __exit__
    raise dj_exc_value.with_traceback(traceback) from exc_value
  File "/Users/vaibhavsingh/Desktop/ASMP25-26/Backend/venv/lib/python3.13/site-packages/django/db/backends/utils.py", line 105, in _execute
    return self.cursor.execute(sql, params)
           ~~~~~~~~~~~~~~~~~~~^^^^^^^^^^^^^
  File "/Users/vaibhavsingh/Desktop/ASMP25-26/Backend/venv/lib/python3.13/site-packages/django/db/backends/sqlite3/base.py", line 360, in execute
    return super().execute(query, params)
           ~~~~~~~~~~~~~~~^^^^^^^^^^^^^^^
django.db.utils.OperationalError: no such column: Authentication_user.reminder_sent
Not Found: /api/mentors/core_engineering/
Not Found: /api/mentors/core_engineering/
Internal Server Error: /admin/Registrations/wishlist/1/change/
Traceback (most recent call last):
  File "/Users/vaibhavsingh/Desktop/ASMP25-26/Backend/venv/lib/python3.13/site-packages/django/db/models/fields/related_descriptors.py", line 243, in __get__
    rel_obj = self.field.get_cached_value(instance)
  File "/Users/vaibhavsingh/Desktop/ASMP25-26/Backend/venv/lib/python3.13/site-packages/django/db/models/fields/mixins.py", line 37, in get_cached_value
    return instance._state.fields_cache[self.cache_name]
           ~~~~~~~~~~~~~~~~~~~~~~~~~~~~^^^^^^^^^^^^^^^^^
KeyError: 'user'

During handling of the above exception, another exception occurred:

Traceback (most recent call last):
  File "/Users/vaibhavsingh/Desktop/ASMP25-26/Backend/venv/lib/python3.13/site-packages/django/db/backends/utils.py", line 105, in _execute
    return self.cursor.execute(sql, params)
           ~~~~~~~~~~~~~~~~~~~^^^^^^^^^^^^^
  File "/Users/vaibhavsingh/Desktop/ASMP25-26/Backend/venv/lib/python3.13/site-packages/django/db/backends/sqlite3/base.py", line 360, in execute
    return super().execute(query, params)
           ~~~~~~~~~~~~~~~^^^^^^^^^^^^^^^
sqlite3.OperationalError: no such column: Authentication_user.reminder_sent

The above exception was the direct cause of the following exception:

Traceback (most recent call last):
  File "/Users/vaibhavsingh/Desktop/ASMP25-26/Backend/venv/lib/python3.13/site-packages/django/core/handlers/exception.py", line 55, in inner
    response = get_response(request)
  File "/Users/vaibhavsingh/Desktop/ASMP25-26/Backend/venv/lib/python3.13/site-packages/django/core/handlers/base.py", line 197, in _get_response
    response = wrapped_callback(request, *callback_args, **callback_kwargs)
  File "/Users/vaibhavsingh/Desktop/ASMP25-26/Backend/venv/lib/python3.13/site-packages/django/contrib/admin/options.py", line 719, in wrapper
    return self.admin_site.admin_view(view)(*args, **kwargs)
           ~~~~~~~~~~~~~~~~~~~~~~~~~~~~~~~~^^^^^^^^^^^^^^^^^
  File "/Users/vaibhavsingh/Desktop/ASMP25-26/Backend/venv/lib/python3.13/site-packages/django/utils/decorators.py", line 192, in _view_wrapper
    result = _process_exception(request, e)
  File "/Users/vaibhavsingh/Desktop/ASMP25-26/Backend/venv/lib/python3.13/site-packages/django/utils/decorators.py", line 190, in _view_wrapper
    response = view_func(request, *args, **kwargs)
  File "/Users/vaibhavsingh/Desktop/ASMP25-26/Backend/venv/lib/python3.13/site-packages/django/views/decorators/cache.py", line 80, in _view_wrapper
    response = view_func(request, *args, **kwargs)
  File "/Users/vaibhavsingh/Desktop/ASMP25-26/Backend/venv/lib/python3.13/site-packages/django/contrib/admin/sites.py", line 246, in inner
    return view(request, *args, **kwargs)
  File "/Users/vaibhavsingh/Desktop/ASMP25-26/Backend/venv/lib/python3.13/site-packages/django/contrib/admin/options.py", line 1987, in change_view
    return self.changeform_view(request, object_id, form_url, extra_context)
           ~~~~~~~~~~~~~~~~~~~~^^^^^^^^^^^^^^^^^^^^^^^^^^^^^^^^^^^^^^^^^^^^^
  File "/Users/vaibhavsingh/Desktop/ASMP25-26/Backend/venv/lib/python3.13/site-packages/django/utils/decorators.py", line 48, in _wrapper
    return bound_method(*args, **kwargs)
  File "/Users/vaibhavsingh/Desktop/ASMP25-26/Backend/venv/lib/python3.13/site-packages/django/utils/decorators.py", line 192, in _view_wrapper
    result = _process_exception(request, e)
  File "/Users/vaibhavsingh/Desktop/ASMP25-26/Backend/venv/lib/python3.13/site-packages/django/utils/decorators.py", line 190, in _view_wrapper
    response = view_func(request, *args, **kwargs)
  File "/Users/vaibhavsingh/Desktop/ASMP25-26/Backend/venv/lib/python3.13/site-packages/django/contrib/admin/options.py", line 1840, in changeform_view
    return self._changeform_view(request, object_id, form_url, extra_context)
           ~~~~~~~~~~~~~~~~~~~~~^^^^^^^^^^^^^^^^^^^^^^^^^^^^^^^^^^^^^^^^^^^^^
  File "/Users/vaibhavsingh/Desktop/ASMP25-26/Backend/venv/lib/python3.13/site-packages/django/contrib/admin/options.py", line 1953, in _changeform_view
    "subtitle": str(obj) if obj else None,
                ~~~^^^^^
  File "/Users/vaibhavsingh/Desktop/ASMP25-26/Backend/Registrations/models.py", line 22, in __str__
    return self.user.ldap+" "+self.user.fullname
           ^^^^^^^^^
  File "/Users/vaibhavsingh/Desktop/ASMP25-26/Backend/venv/lib/python3.13/site-packages/django/db/models/fields/related_descriptors.py", line 261, in __get__
    rel_obj = self.get_object(instance)
  File "/Users/vaibhavsingh/Desktop/ASMP25-26/Backend/venv/lib/python3.13/site-packages/django/db/models/fields/related_descriptors.py", line 391, in get_object
    return super().get_object(instance)
           ~~~~~~~~~~~~~~~~~~^^^^^^^^^^
  File "/Users/vaibhavsingh/Desktop/ASMP25-26/Backend/venv/lib/python3.13/site-packages/django/db/models/fields/related_descriptors.py", line 224, in get_object
    return qs.get(self.field.get_reverse_related_filter(instance))
           ~~~~~~^^^^^^^^^^^^^^^^^^^^^^^^^^^^^^^^^^^^^^^^^^^^^^^^^
  File "/Users/vaibhavsingh/Desktop/ASMP25-26/Backend/venv/lib/python3.13/site-packages/django/db/models/query.py", line 629, in get
    num = len(clone)
  File "/Users/vaibhavsingh/Desktop/ASMP25-26/Backend/venv/lib/python3.13/site-packages/django/db/models/query.py", line 366, in __len__
    self._fetch_all()
    ~~~~~~~~~~~~~~~^^
  File "/Users/vaibhavsingh/Desktop/ASMP25-26/Backend/venv/lib/python3.13/site-packages/django/db/models/query.py", line 1949, in _fetch_all
    self._result_cache = list(self._iterable_class(self))
                         ~~~~^^^^^^^^^^^^^^^^^^^^^^^^^^^^
  File "/Users/vaibhavsingh/Desktop/ASMP25-26/Backend/venv/lib/python3.13/site-packages/django/db/models/query.py", line 91, in __iter__
    results = compiler.execute_sql(
        chunked_fetch=self.chunked_fetch, chunk_size=self.chunk_size
    )
  File "/Users/vaibhavsingh/Desktop/ASMP25-26/Backend/venv/lib/python3.13/site-packages/django/db/models/sql/compiler.py", line 1623, in execute_sql
    cursor.execute(sql, params)
    ~~~~~~~~~~~~~~^^^^^^^^^^^^^
  File "/Users/vaibhavsingh/Desktop/ASMP25-26/Backend/venv/lib/python3.13/site-packages/django/db/backends/utils.py", line 122, in execute
    return super().execute(sql, params)
           ~~~~~~~~~~~~~~~^^^^^^^^^^^^^
  File "/Users/vaibhavsingh/Desktop/ASMP25-26/Backend/venv/lib/python3.13/site-packages/django/db/backends/utils.py", line 79, in execute
    return self._execute_with_wrappers(
           ~~~~~~~~~~~~~~~~~~~~~~~~~~~^
        sql, params, many=False, executor=self._execute
        ^^^^^^^^^^^^^^^^^^^^^^^^^^^^^^^^^^^^^^^^^^^^^^^
    )
    ^
  File "/Users/vaibhavsingh/Desktop/ASMP25-26/Backend/venv/lib/python3.13/site-packages/django/db/backends/utils.py", line 92, in _execute_with_wrappers
    return executor(sql, params, many, context)
  File "/Users/vaibhavsingh/Desktop/ASMP25-26/Backend/venv/lib/python3.13/site-packages/django/db/backends/utils.py", line 100, in _execute
    with self.db.wrap_database_errors:
         ^^^^^^^^^^^^^^^^^^^^^^^^^^^^
  File "/Users/vaibhavsingh/Desktop/ASMP25-26/Backend/venv/lib/python3.13/site-packages/django/db/utils.py", line 91, in __exit__
    raise dj_exc_value.with_traceback(traceback) from exc_value
  File "/Users/vaibhavsingh/Desktop/ASMP25-26/Backend/venv/lib/python3.13/site-packages/django/db/backends/utils.py", line 105, in _execute
    return self.cursor.execute(sql, params)
           ~~~~~~~~~~~~~~~~~~~^^^^^^^^^^^^^
  File "/Users/vaibhavsingh/Desktop/ASMP25-26/Backend/venv/lib/python3.13/site-packages/django/db/backends/sqlite3/base.py", line 360, in execute
    return super().execute(query, params)
           ~~~~~~~~~~~~~~~^^^^^^^^^^^^^^^
django.db.utils.OperationalError: no such column: Authentication_user.reminder_sent
Not Found: /api/mentors/core_engineering/
Not Found: /api/mentors/core_engineering/
Internal Server Error: /api/registration/wishlist/
Traceback (most recent call last):
  File "/Users/vaibhavsingh/Desktop/ASMP25-26/Backend/venv/lib/python3.13/site-packages/django/db/backends/utils.py", line 105, in _execute
    return self.cursor.execute(sql, params)
           ~~~~~~~~~~~~~~~~~~~^^^^^^^^^^^^^
  File "/Users/vaibhavsingh/Desktop/ASMP25-26/Backend/venv/lib/python3.13/site-packages/django/db/backends/sqlite3/base.py", line 360, in execute
    return super().execute(query, params)
           ~~~~~~~~~~~~~~~^^^^^^^^^^^^^^^
sqlite3.OperationalError: no such column: Authentication_user.reminder_sent

The above exception was the direct cause of the following exception:

Traceback (most recent call last):
  File "/Users/vaibhavsingh/Desktop/ASMP25-26/Backend/venv/lib/python3.13/site-packages/django/core/handlers/exception.py", line 55, in inner
    response = get_response(request)
  File "/Users/vaibhavsingh/Desktop/ASMP25-26/Backend/venv/lib/python3.13/site-packages/django/core/handlers/base.py", line 197, in _get_response
    response = wrapped_callback(request, *callback_args, **callback_kwargs)
  File "/Users/vaibhavsingh/Desktop/ASMP25-26/Backend/venv/lib/python3.13/site-packages/django/views/decorators/csrf.py", line 65, in _view_wrapper
    return view_func(request, *args, **kwargs)
  File "/Users/vaibhavsingh/Desktop/ASMP25-26/Backend/venv/lib/python3.13/site-packages/django/views/generic/base.py", line 105, in view
    return self.dispatch(request, *args, **kwargs)
           ~~~~~~~~~~~~~^^^^^^^^^^^^^^^^^^^^^^^^^^
  File "/Users/vaibhavsingh/Desktop/ASMP25-26/Backend/venv/lib/python3.13/site-packages/rest_framework/views.py", line 515, in dispatch
    response = self.handle_exception(exc)
  File "/Users/vaibhavsingh/Desktop/ASMP25-26/Backend/venv/lib/python3.13/site-packages/rest_framework/views.py", line 475, in handle_exception
    self.raise_uncaught_exception(exc)
    ~~~~~~~~~~~~~~~~~~~~~~~~~~~~~^^^^^
  File "/Users/vaibhavsingh/Desktop/ASMP25-26/Backend/venv/lib/python3.13/site-packages/rest_framework/views.py", line 486, in raise_uncaught_exception
    raise exc
  File "/Users/vaibhavsingh/Desktop/ASMP25-26/Backend/venv/lib/python3.13/site-packages/rest_framework/views.py", line 512, in dispatch
    response = handler(request, *args, **kwargs)
  File "/Users/vaibhavsingh/Desktop/ASMP25-26/Backend/Registrations/views.py", line 184, in get
    user = User.objects.get(accessToken=accessToken)
  File "/Users/vaibhavsingh/Desktop/ASMP25-26/Backend/venv/lib/python3.13/site-packages/django/db/models/manager.py", line 87, in manager_method
    return getattr(self.get_queryset(), name)(*args, **kwargs)
           ~~~~~~~~~~~~~~~~~~~~~~~~~~~~~~~~~~^^^^^^^^^^^^^^^^^
  File "/Users/vaibhavsingh/Desktop/ASMP25-26/Backend/venv/lib/python3.13/site-packages/django/db/models/query.py", line 629, in get
    num = len(clone)
  File "/Users/vaibhavsingh/Desktop/ASMP25-26/Backend/venv/lib/python3.13/site-packages/django/db/models/query.py", line 366, in __len__
    self._fetch_all()
    ~~~~~~~~~~~~~~~^^
  File "/Users/vaibhavsingh/Desktop/ASMP25-26/Backend/venv/lib/python3.13/site-packages/django/db/models/query.py", line 1949, in _fetch_all
    self._result_cache = list(self._iterable_class(self))
                         ~~~~^^^^^^^^^^^^^^^^^^^^^^^^^^^^
  File "/Users/vaibhavsingh/Desktop/ASMP25-26/Backend/venv/lib/python3.13/site-packages/django/db/models/query.py", line 91, in __iter__
    results = compiler.execute_sql(
        chunked_fetch=self.chunked_fetch, chunk_size=self.chunk_size
    )
  File "/Users/vaibhavsingh/Desktop/ASMP25-26/Backend/venv/lib/python3.13/site-packages/django/db/models/sql/compiler.py", line 1623, in execute_sql
    cursor.execute(sql, params)
    ~~~~~~~~~~~~~~^^^^^^^^^^^^^
  File "/Users/vaibhavsingh/Desktop/ASMP25-26/Backend/venv/lib/python3.13/site-packages/django/db/backends/utils.py", line 122, in execute
    return super().execute(sql, params)
           ~~~~~~~~~~~~~~~^^^^^^^^^^^^^
  File "/Users/vaibhavsingh/Desktop/ASMP25-26/Backend/venv/lib/python3.13/site-packages/django/db/backends/utils.py", line 79, in execute
    return self._execute_with_wrappers(
           ~~~~~~~~~~~~~~~~~~~~~~~~~~~^
        sql, params, many=False, executor=self._execute
        ^^^^^^^^^^^^^^^^^^^^^^^^^^^^^^^^^^^^^^^^^^^^^^^
    )
    ^
  File "/Users/vaibhavsingh/Desktop/ASMP25-26/Backend/venv/lib/python3.13/site-packages/django/db/backends/utils.py", line 92, in _execute_with_wrappers
    return executor(sql, params, many, context)
  File "/Users/vaibhavsingh/Desktop/ASMP25-26/Backend/venv/lib/python3.13/site-packages/django/db/backends/utils.py", line 100, in _execute
    with self.db.wrap_database_errors:
         ^^^^^^^^^^^^^^^^^^^^^^^^^^^^
  File "/Users/vaibhavsingh/Desktop/ASMP25-26/Backend/venv/lib/python3.13/site-packages/django/db/utils.py", line 91, in __exit__
    raise dj_exc_value.with_traceback(traceback) from exc_value
  File "/Users/vaibhavsingh/Desktop/ASMP25-26/Backend/venv/lib/python3.13/site-packages/django/db/backends/utils.py", line 105, in _execute
    return self.cursor.execute(sql, params)
           ~~~~~~~~~~~~~~~~~~~^^^^^^^^^^^^^
  File "/Users/vaibhavsingh/Desktop/ASMP25-26/Backend/venv/lib/python3.13/site-packages/django/db/backends/sqlite3/base.py", line 360, in execute
    return super().execute(query, params)
           ~~~~~~~~~~~~~~~^^^^^^^^^^^^^^^
django.db.utils.OperationalError: no such column: Authentication_user.reminder_sent
Internal Server Error: /api/registration/wishlist/
Traceback (most recent call last):
  File "/Users/vaibhavsingh/Desktop/ASMP25-26/Backend/venv/lib/python3.13/site-packages/django/db/backends/utils.py", line 105, in _execute
    return self.cursor.execute(sql, params)
           ~~~~~~~~~~~~~~~~~~~^^^^^^^^^^^^^
  File "/Users/vaibhavsingh/Desktop/ASMP25-26/Backend/venv/lib/python3.13/site-packages/django/db/backends/sqlite3/base.py", line 360, in execute
    return super().execute(query, params)
           ~~~~~~~~~~~~~~~^^^^^^^^^^^^^^^
sqlite3.OperationalError: no such column: Authentication_user.reminder_sent

The above exception was the direct cause of the following exception:

Traceback (most recent call last):
  File "/Users/vaibhavsingh/Desktop/ASMP25-26/Backend/venv/lib/python3.13/site-packages/django/core/handlers/exception.py", line 55, in inner
    response = get_response(request)
  File "/Users/vaibhavsingh/Desktop/ASMP25-26/Backend/venv/lib/python3.13/site-packages/django/core/handlers/base.py", line 197, in _get_response
    response = wrapped_callback(request, *callback_args, **callback_kwargs)
  File "/Users/vaibhavsingh/Desktop/ASMP25-26/Backend/venv/lib/python3.13/site-packages/django/views/decorators/csrf.py", line 65, in _view_wrapper
    return view_func(request, *args, **kwargs)
  File "/Users/vaibhavsingh/Desktop/ASMP25-26/Backend/venv/lib/python3.13/site-packages/django/views/generic/base.py", line 105, in view
    return self.dispatch(request, *args, **kwargs)
           ~~~~~~~~~~~~~^^^^^^^^^^^^^^^^^^^^^^^^^^
  File "/Users/vaibhavsingh/Desktop/ASMP25-26/Backend/venv/lib/python3.13/site-packages/rest_framework/views.py", line 515, in dispatch
    response = self.handle_exception(exc)
  File "/Users/vaibhavsingh/Desktop/ASMP25-26/Backend/venv/lib/python3.13/site-packages/rest_framework/views.py", line 475, in handle_exception
    self.raise_uncaught_exception(exc)
    ~~~~~~~~~~~~~~~~~~~~~~~~~~~~~^^^^^
  File "/Users/vaibhavsingh/Desktop/ASMP25-26/Backend/venv/lib/python3.13/site-packages/rest_framework/views.py", line 486, in raise_uncaught_exception
    raise exc
  File "/Users/vaibhavsingh/Desktop/ASMP25-26/Backend/venv/lib/python3.13/site-packages/rest_framework/views.py", line 512, in dispatch
    response = handler(request, *args, **kwargs)
  File "/Users/vaibhavsingh/Desktop/ASMP25-26/Backend/Registrations/views.py", line 184, in get
    user = User.objects.get(accessToken=accessToken)
  File "/Users/vaibhavsingh/Desktop/ASMP25-26/Backend/venv/lib/python3.13/site-packages/django/db/models/manager.py", line 87, in manager_method
    return getattr(self.get_queryset(), name)(*args, **kwargs)
           ~~~~~~~~~~~~~~~~~~~~~~~~~~~~~~~~~~^^^^^^^^^^^^^^^^^
  File "/Users/vaibhavsingh/Desktop/ASMP25-26/Backend/venv/lib/python3.13/site-packages/django/db/models/query.py", line 629, in get
    num = len(clone)
  File "/Users/vaibhavsingh/Desktop/ASMP25-26/Backend/venv/lib/python3.13/site-packages/django/db/models/query.py", line 366, in __len__
    self._fetch_all()
    ~~~~~~~~~~~~~~~^^
  File "/Users/vaibhavsingh/Desktop/ASMP25-26/Backend/venv/lib/python3.13/site-packages/django/db/models/query.py", line 1949, in _fetch_all
    self._result_cache = list(self._iterable_class(self))
                         ~~~~^^^^^^^^^^^^^^^^^^^^^^^^^^^^
  File "/Users/vaibhavsingh/Desktop/ASMP25-26/Backend/venv/lib/python3.13/site-packages/django/db/models/query.py", line 91, in __iter__
    results = compiler.execute_sql(
        chunked_fetch=self.chunked_fetch, chunk_size=self.chunk_size
    )
  File "/Users/vaibhavsingh/Desktop/ASMP25-26/Backend/venv/lib/python3.13/site-packages/django/db/models/sql/compiler.py", line 1623, in execute_sql
    cursor.execute(sql, params)
    ~~~~~~~~~~~~~~^^^^^^^^^^^^^
  File "/Users/vaibhavsingh/Desktop/ASMP25-26/Backend/venv/lib/python3.13/site-packages/django/db/backends/utils.py", line 122, in execute
    return super().execute(sql, params)
           ~~~~~~~~~~~~~~~^^^^^^^^^^^^^
  File "/Users/vaibhavsingh/Desktop/ASMP25-26/Backend/venv/lib/python3.13/site-packages/django/db/backends/utils.py", line 79, in execute
    return self._execute_with_wrappers(
           ~~~~~~~~~~~~~~~~~~~~~~~~~~~^
        sql, params, many=False, executor=self._execute
        ^^^^^^^^^^^^^^^^^^^^^^^^^^^^^^^^^^^^^^^^^^^^^^^
    )
    ^
  File "/Users/vaibhavsingh/Desktop/ASMP25-26/Backend/venv/lib/python3.13/site-packages/django/db/backends/utils.py", line 92, in _execute_with_wrappers
    return executor(sql, params, many, context)
  File "/Users/vaibhavsingh/Desktop/ASMP25-26/Backend/venv/lib/python3.13/site-packages/django/db/backends/utils.py", line 100, in _execute
    with self.db.wrap_database_errors:
         ^^^^^^^^^^^^^^^^^^^^^^^^^^^^
  File "/Users/vaibhavsingh/Desktop/ASMP25-26/Backend/venv/lib/python3.13/site-packages/django/db/utils.py", line 91, in __exit__
    raise dj_exc_value.with_traceback(traceback) from exc_value
  File "/Users/vaibhavsingh/Desktop/ASMP25-26/Backend/venv/lib/python3.13/site-packages/django/db/backends/utils.py", line 105, in _execute
    return self.cursor.execute(sql, params)
           ~~~~~~~~~~~~~~~~~~~^^^^^^^^^^^^^
  File "/Users/vaibhavsingh/Desktop/ASMP25-26/Backend/venv/lib/python3.13/site-packages/django/db/backends/sqlite3/base.py", line 360, in execute
    return super().execute(query, params)
           ~~~~~~~~~~~~~~~^^^^^^^^^^^^^^^
django.db.utils.OperationalError: no such column: Authentication_user.reminder_sent
Not Found: /api/authentication/profile/
Not Found: /api/authentication/profile/
Watching for file changes with StatReloader
Not Found: /api/authentication/profile/
Not Found: /api/authentication/profile/
Watching for file changes with StatReloader
Internal Server Error: /api/registration/wishlist/
Traceback (most recent call last):
  File "/Users/vaibhavsingh/Desktop/ASMP25-26/Backend/venv/lib/python3.13/site-packages/django/db/backends/utils.py", line 105, in _execute
    return self.cursor.execute(sql, params)
           ~~~~~~~~~~~~~~~~~~~^^^^^^^^^^^^^
  File "/Users/vaibhavsingh/Desktop/ASMP25-26/Backend/venv/lib/python3.13/site-packages/django/db/backends/sqlite3/base.py", line 360, in execute
    return super().execute(query, params)
           ~~~~~~~~~~~~~~~^^^^^^^^^^^^^^^
sqlite3.OperationalError: no such column: Authentication_user.reminder_sent

The above exception was the direct cause of the following exception:

Traceback (most recent call last):
  File "/Users/vaibhavsingh/Desktop/ASMP25-26/Backend/venv/lib/python3.13/site-packages/django/core/handlers/exception.py", line 55, in inner
    response = get_response(request)
  File "/Users/vaibhavsingh/Desktop/ASMP25-26/Backend/venv/lib/python3.13/site-packages/django/core/handlers/base.py", line 197, in _get_response
    response = wrapped_callback(request, *callback_args, **callback_kwargs)
  File "/Users/vaibhavsingh/Desktop/ASMP25-26/Backend/venv/lib/python3.13/site-packages/django/views/decorators/csrf.py", line 65, in _view_wrapper
    return view_func(request, *args, **kwargs)
  File "/Users/vaibhavsingh/Desktop/ASMP25-26/Backend/venv/lib/python3.13/site-packages/django/views/generic/base.py", line 105, in view
    return self.dispatch(request, *args, **kwargs)
           ~~~~~~~~~~~~~^^^^^^^^^^^^^^^^^^^^^^^^^^
  File "/Users/vaibhavsingh/Desktop/ASMP25-26/Backend/venv/lib/python3.13/site-packages/rest_framework/views.py", line 515, in dispatch
    response = self.handle_exception(exc)
  File "/Users/vaibhavsingh/Desktop/ASMP25-26/Backend/venv/lib/python3.13/site-packages/rest_framework/views.py", line 475, in handle_exception
    self.raise_uncaught_exception(exc)
    ~~~~~~~~~~~~~~~~~~~~~~~~~~~~~^^^^^
  File "/Users/vaibhavsingh/Desktop/ASMP25-26/Backend/venv/lib/python3.13/site-packages/rest_framework/views.py", line 486, in raise_uncaught_exception
    raise exc
  File "/Users/vaibhavsingh/Desktop/ASMP25-26/Backend/venv/lib/python3.13/site-packages/rest_framework/views.py", line 512, in dispatch
    response = handler(request, *args, **kwargs)
  File "/Users/vaibhavsingh/Desktop/ASMP25-26/Backend/Registrations/views.py", line 184, in get
    user = User.objects.get(accessToken=accessToken)
  File "/Users/vaibhavsingh/Desktop/ASMP25-26/Backend/venv/lib/python3.13/site-packages/django/db/models/manager.py", line 87, in manager_method
    return getattr(self.get_queryset(), name)(*args, **kwargs)
           ~~~~~~~~~~~~~~~~~~~~~~~~~~~~~~~~~~^^^^^^^^^^^^^^^^^
  File "/Users/vaibhavsingh/Desktop/ASMP25-26/Backend/venv/lib/python3.13/site-packages/django/db/models/query.py", line 629, in get
    num = len(clone)
  File "/Users/vaibhavsingh/Desktop/ASMP25-26/Backend/venv/lib/python3.13/site-packages/django/db/models/query.py", line 366, in __len__
    self._fetch_all()
    ~~~~~~~~~~~~~~~^^
  File "/Users/vaibhavsingh/Desktop/ASMP25-26/Backend/venv/lib/python3.13/site-packages/django/db/models/query.py", line 1949, in _fetch_all
    self._result_cache = list(self._iterable_class(self))
                         ~~~~^^^^^^^^^^^^^^^^^^^^^^^^^^^^
  File "/Users/vaibhavsingh/Desktop/ASMP25-26/Backend/venv/lib/python3.13/site-packages/django/db/models/query.py", line 91, in __iter__
    results = compiler.execute_sql(
        chunked_fetch=self.chunked_fetch, chunk_size=self.chunk_size
    )
  File "/Users/vaibhavsingh/Desktop/ASMP25-26/Backend/venv/lib/python3.13/site-packages/django/db/models/sql/compiler.py", line 1623, in execute_sql
    cursor.execute(sql, params)
    ~~~~~~~~~~~~~~^^^^^^^^^^^^^
  File "/Users/vaibhavsingh/Desktop/ASMP25-26/Backend/venv/lib/python3.13/site-packages/django/db/backends/utils.py", line 122, in execute
    return super().execute(sql, params)
           ~~~~~~~~~~~~~~~^^^^^^^^^^^^^
  File "/Users/vaibhavsingh/Desktop/ASMP25-26/Backend/venv/lib/python3.13/site-packages/django/db/backends/utils.py", line 79, in execute
    return self._execute_with_wrappers(
           ~~~~~~~~~~~~~~~~~~~~~~~~~~~^
        sql, params, many=False, executor=self._execute
        ^^^^^^^^^^^^^^^^^^^^^^^^^^^^^^^^^^^^^^^^^^^^^^^
    )
    ^
  File "/Users/vaibhavsingh/Desktop/ASMP25-26/Backend/venv/lib/python3.13/site-packages/django/db/backends/utils.py", line 92, in _execute_with_wrappers
    return executor(sql, params, many, context)
  File "/Users/vaibhavsingh/Desktop/ASMP25-26/Backend/venv/lib/python3.13/site-packages/django/db/backends/utils.py", line 100, in _execute
    with self.db.wrap_database_errors:
         ^^^^^^^^^^^^^^^^^^^^^^^^^^^^
  File "/Users/vaibhavsingh/Desktop/ASMP25-26/Backend/venv/lib/python3.13/site-packages/django/db/utils.py", line 91, in __exit__
    raise dj_exc_value.with_traceback(traceback) from exc_value
  File "/Users/vaibhavsingh/Desktop/ASMP25-26/Backend/venv/lib/python3.13/site-packages/django/db/backends/utils.py", line 105, in _execute
    return self.cursor.execute(sql, params)
           ~~~~~~~~~~~~~~~~~~~^^^^^^^^^^^^^
  File "/Users/vaibhavsingh/Desktop/ASMP25-26/Backend/venv/lib/python3.13/site-packages/django/db/backends/sqlite3/base.py", line 360, in execute
    return super().execute(query, params)
           ~~~~~~~~~~~~~~~^^^^^^^^^^^^^^^
django.db.utils.OperationalError: no such column: Authentication_user.reminder_sent
Internal Server Error: /api/registration/wishlist/
Traceback (most recent call last):
  File "/Users/vaibhavsingh/Desktop/ASMP25-26/Backend/venv/lib/python3.13/site-packages/django/db/backends/utils.py", line 105, in _execute
    return self.cursor.execute(sql, params)
           ~~~~~~~~~~~~~~~~~~~^^^^^^^^^^^^^
  File "/Users/vaibhavsingh/Desktop/ASMP25-26/Backend/venv/lib/python3.13/site-packages/django/db/backends/sqlite3/base.py", line 360, in execute
    return super().execute(query, params)
           ~~~~~~~~~~~~~~~^^^^^^^^^^^^^^^
sqlite3.OperationalError: no such column: Authentication_user.reminder_sent

The above exception was the direct cause of the following exception:

Traceback (most recent call last):
  File "/Users/vaibhavsingh/Desktop/ASMP25-26/Backend/venv/lib/python3.13/site-packages/django/core/handlers/exception.py", line 55, in inner
    response = get_response(request)
  File "/Users/vaibhavsingh/Desktop/ASMP25-26/Backend/venv/lib/python3.13/site-packages/django/core/handlers/base.py", line 197, in _get_response
    response = wrapped_callback(request, *callback_args, **callback_kwargs)
  File "/Users/vaibhavsingh/Desktop/ASMP25-26/Backend/venv/lib/python3.13/site-packages/django/views/decorators/csrf.py", line 65, in _view_wrapper
    return view_func(request, *args, **kwargs)
  File "/Users/vaibhavsingh/Desktop/ASMP25-26/Backend/venv/lib/python3.13/site-packages/django/views/generic/base.py", line 105, in view
    return self.dispatch(request, *args, **kwargs)
           ~~~~~~~~~~~~~^^^^^^^^^^^^^^^^^^^^^^^^^^
  File "/Users/vaibhavsingh/Desktop/ASMP25-26/Backend/venv/lib/python3.13/site-packages/rest_framework/views.py", line 515, in dispatch
    response = self.handle_exception(exc)
  File "/Users/vaibhavsingh/Desktop/ASMP25-26/Backend/venv/lib/python3.13/site-packages/rest_framework/views.py", line 475, in handle_exception
    self.raise_uncaught_exception(exc)
    ~~~~~~~~~~~~~~~~~~~~~~~~~~~~~^^^^^
  File "/Users/vaibhavsingh/Desktop/ASMP25-26/Backend/venv/lib/python3.13/site-packages/rest_framework/views.py", line 486, in raise_uncaught_exception
    raise exc
  File "/Users/vaibhavsingh/Desktop/ASMP25-26/Backend/venv/lib/python3.13/site-packages/rest_framework/views.py", line 512, in dispatch
    response = handler(request, *args, **kwargs)
  File "/Users/vaibhavsingh/Desktop/ASMP25-26/Backend/Registrations/views.py", line 184, in get
    user = User.objects.get(accessToken=accessToken)
  File "/Users/vaibhavsingh/Desktop/ASMP25-26/Backend/venv/lib/python3.13/site-packages/django/db/models/manager.py", line 87, in manager_method
    return getattr(self.get_queryset(), name)(*args, **kwargs)
           ~~~~~~~~~~~~~~~~~~~~~~~~~~~~~~~~~~^^^^^^^^^^^^^^^^^
  File "/Users/vaibhavsingh/Desktop/ASMP25-26/Backend/venv/lib/python3.13/site-packages/django/db/models/query.py", line 629, in get
    num = len(clone)
  File "/Users/vaibhavsingh/Desktop/ASMP25-26/Backend/venv/lib/python3.13/site-packages/django/db/models/query.py", line 366, in __len__
    self._fetch_all()
    ~~~~~~~~~~~~~~~^^
  File "/Users/vaibhavsingh/Desktop/ASMP25-26/Backend/venv/lib/python3.13/site-packages/django/db/models/query.py", line 1949, in _fetch_all
    self._result_cache = list(self._iterable_class(self))
                         ~~~~^^^^^^^^^^^^^^^^^^^^^^^^^^^^
  File "/Users/vaibhavsingh/Desktop/ASMP25-26/Backend/venv/lib/python3.13/site-packages/django/db/models/query.py", line 91, in __iter__
    results = compiler.execute_sql(
        chunked_fetch=self.chunked_fetch, chunk_size=self.chunk_size
    )
  File "/Users/vaibhavsingh/Desktop/ASMP25-26/Backend/venv/lib/python3.13/site-packages/django/db/models/sql/compiler.py", line 1623, in execute_sql
    cursor.execute(sql, params)
    ~~~~~~~~~~~~~~^^^^^^^^^^^^^
  File "/Users/vaibhavsingh/Desktop/ASMP25-26/Backend/venv/lib/python3.13/site-packages/django/db/backends/utils.py", line 122, in execute
    return super().execute(sql, params)
           ~~~~~~~~~~~~~~~^^^^^^^^^^^^^
  File "/Users/vaibhavsingh/Desktop/ASMP25-26/Backend/venv/lib/python3.13/site-packages/django/db/backends/utils.py", line 79, in execute
    return self._execute_with_wrappers(
           ~~~~~~~~~~~~~~~~~~~~~~~~~~~^
        sql, params, many=False, executor=self._execute
        ^^^^^^^^^^^^^^^^^^^^^^^^^^^^^^^^^^^^^^^^^^^^^^^
    )
    ^
  File "/Users/vaibhavsingh/Desktop/ASMP25-26/Backend/venv/lib/python3.13/site-packages/django/db/backends/utils.py", line 92, in _execute_with_wrappers
    return executor(sql, params, many, context)
  File "/Users/vaibhavsingh/Desktop/ASMP25-26/Backend/venv/lib/python3.13/site-packages/django/db/backends/utils.py", line 100, in _execute
    with self.db.wrap_database_errors:
         ^^^^^^^^^^^^^^^^^^^^^^^^^^^^
  File "/Users/vaibhavsingh/Desktop/ASMP25-26/Backend/venv/lib/python3.13/site-packages/django/db/utils.py", line 91, in __exit__
    raise dj_exc_value.with_traceback(traceback) from exc_value
  File "/Users/vaibhavsingh/Desktop/ASMP25-26/Backend/venv/lib/python3.13/site-packages/django/db/backends/utils.py", line 105, in _execute
    return self.cursor.execute(sql, params)
           ~~~~~~~~~~~~~~~~~~~^^^^^^^^^^^^^
  File "/Users/vaibhavsingh/Desktop/ASMP25-26/Backend/venv/lib/python3.13/site-packages/django/db/backends/sqlite3/base.py", line 360, in execute
    return super().execute(query, params)
           ~~~~~~~~~~~~~~~^^^^^^^^^^^^^^^
django.db.utils.OperationalError: no such column: Authentication_user.reminder_sent
Not Found: /api/mentors/core_engineering/
Not Found: /api/mentors/core_engineering/
Internal Server Error: /api/registration/wishlist/
Traceback (most recent call last):
  File "/Users/vaibhavsingh/Desktop/ASMP25-26/Backend/venv/lib/python3.13/site-packages/django/db/backends/utils.py", line 105, in _execute
    return self.cursor.execute(sql, params)
           ~~~~~~~~~~~~~~~~~~~^^^^^^^^^^^^^
  File "/Users/vaibhavsingh/Desktop/ASMP25-26/Backend/venv/lib/python3.13/site-packages/django/db/backends/sqlite3/base.py", line 360, in execute
    return super().execute(query, params)
           ~~~~~~~~~~~~~~~^^^^^^^^^^^^^^^
sqlite3.OperationalError: no such column: Authentication_user.reminder_sent

The above exception was the direct cause of the following exception:

Traceback (most recent call last):
  File "/Users/vaibhavsingh/Desktop/ASMP25-26/Backend/venv/lib/python3.13/site-packages/django/core/handlers/exception.py", line 55, in inner
    response = get_response(request)
  File "/Users/vaibhavsingh/Desktop/ASMP25-26/Backend/venv/lib/python3.13/site-packages/django/core/handlers/base.py", line 197, in _get_response
    response = wrapped_callback(request, *callback_args, **callback_kwargs)
  File "/Users/vaibhavsingh/Desktop/ASMP25-26/Backend/venv/lib/python3.13/site-packages/django/views/decorators/csrf.py", line 65, in _view_wrapper
    return view_func(request, *args, **kwargs)
  File "/Users/vaibhavsingh/Desktop/ASMP25-26/Backend/venv/lib/python3.13/site-packages/django/views/generic/base.py", line 105, in view
    return self.dispatch(request, *args, **kwargs)
           ~~~~~~~~~~~~~^^^^^^^^^^^^^^^^^^^^^^^^^^
  File "/Users/vaibhavsingh/Desktop/ASMP25-26/Backend/venv/lib/python3.13/site-packages/rest_framework/views.py", line 515, in dispatch
    response = self.handle_exception(exc)
  File "/Users/vaibhavsingh/Desktop/ASMP25-26/Backend/venv/lib/python3.13/site-packages/rest_framework/views.py", line 475, in handle_exception
    self.raise_uncaught_exception(exc)
    ~~~~~~~~~~~~~~~~~~~~~~~~~~~~~^^^^^
  File "/Users/vaibhavsingh/Desktop/ASMP25-26/Backend/venv/lib/python3.13/site-packages/rest_framework/views.py", line 486, in raise_uncaught_exception
    raise exc
  File "/Users/vaibhavsingh/Desktop/ASMP25-26/Backend/venv/lib/python3.13/site-packages/rest_framework/views.py", line 512, in dispatch
    response = handler(request, *args, **kwargs)
  File "/Users/vaibhavsingh/Desktop/ASMP25-26/Backend/Registrations/views.py", line 184, in get
    user = User.objects.get(accessToken=accessToken)
  File "/Users/vaibhavsingh/Desktop/ASMP25-26/Backend/venv/lib/python3.13/site-packages/django/db/models/manager.py", line 87, in manager_method
    return getattr(self.get_queryset(), name)(*args, **kwargs)
           ~~~~~~~~~~~~~~~~~~~~~~~~~~~~~~~~~~^^^^^^^^^^^^^^^^^
  File "/Users/vaibhavsingh/Desktop/ASMP25-26/Backend/venv/lib/python3.13/site-packages/django/db/models/query.py", line 629, in get
    num = len(clone)
  File "/Users/vaibhavsingh/Desktop/ASMP25-26/Backend/venv/lib/python3.13/site-packages/django/db/models/query.py", line 366, in __len__
    self._fetch_all()
    ~~~~~~~~~~~~~~~^^
  File "/Users/vaibhavsingh/Desktop/ASMP25-26/Backend/venv/lib/python3.13/site-packages/django/db/models/query.py", line 1949, in _fetch_all
    self._result_cache = list(self._iterable_class(self))
                         ~~~~^^^^^^^^^^^^^^^^^^^^^^^^^^^^
  File "/Users/vaibhavsingh/Desktop/ASMP25-26/Backend/venv/lib/python3.13/site-packages/django/db/models/query.py", line 91, in __iter__
    results = compiler.execute_sql(
        chunked_fetch=self.chunked_fetch, chunk_size=self.chunk_size
    )
  File "/Users/vaibhavsingh/Desktop/ASMP25-26/Backend/venv/lib/python3.13/site-packages/django/db/models/sql/compiler.py", line 1623, in execute_sql
    cursor.execute(sql, params)
    ~~~~~~~~~~~~~~^^^^^^^^^^^^^
  File "/Users/vaibhavsingh/Desktop/ASMP25-26/Backend/venv/lib/python3.13/site-packages/django/db/backends/utils.py", line 122, in execute
    return super().execute(sql, params)
           ~~~~~~~~~~~~~~~^^^^^^^^^^^^^
  File "/Users/vaibhavsingh/Desktop/ASMP25-26/Backend/venv/lib/python3.13/site-packages/django/db/backends/utils.py", line 79, in execute
    return self._execute_with_wrappers(
           ~~~~~~~~~~~~~~~~~~~~~~~~~~~^
        sql, params, many=False, executor=self._execute
        ^^^^^^^^^^^^^^^^^^^^^^^^^^^^^^^^^^^^^^^^^^^^^^^
    )
    ^
  File "/Users/vaibhavsingh/Desktop/ASMP25-26/Backend/venv/lib/python3.13/site-packages/django/db/backends/utils.py", line 92, in _execute_with_wrappers
    return executor(sql, params, many, context)
  File "/Users/vaibhavsingh/Desktop/ASMP25-26/Backend/venv/lib/python3.13/site-packages/django/db/backends/utils.py", line 100, in _execute
    with self.db.wrap_database_errors:
         ^^^^^^^^^^^^^^^^^^^^^^^^^^^^
  File "/Users/vaibhavsingh/Desktop/ASMP25-26/Backend/venv/lib/python3.13/site-packages/django/db/utils.py", line 91, in __exit__
    raise dj_exc_value.with_traceback(traceback) from exc_value
  File "/Users/vaibhavsingh/Desktop/ASMP25-26/Backend/venv/lib/python3.13/site-packages/django/db/backends/utils.py", line 105, in _execute
    return self.cursor.execute(sql, params)
           ~~~~~~~~~~~~~~~~~~~^^^^^^^^^^^^^
  File "/Users/vaibhavsingh/Desktop/ASMP25-26/Backend/venv/lib/python3.13/site-packages/django/db/backends/sqlite3/base.py", line 360, in execute
    return super().execute(query, params)
           ~~~~~~~~~~~~~~~^^^^^^^^^^^^^^^
django.db.utils.OperationalError: no such column: Authentication_user.reminder_sent
Internal Server Error: /api/registration/wishlist/
Traceback (most recent call last):
  File "/Users/vaibhavsingh/Desktop/ASMP25-26/Backend/venv/lib/python3.13/site-packages/django/db/backends/utils.py", line 105, in _execute
    return self.cursor.execute(sql, params)
           ~~~~~~~~~~~~~~~~~~~^^^^^^^^^^^^^
  File "/Users/vaibhavsingh/Desktop/ASMP25-26/Backend/venv/lib/python3.13/site-packages/django/db/backends/sqlite3/base.py", line 360, in execute
    return super().execute(query, params)
           ~~~~~~~~~~~~~~~^^^^^^^^^^^^^^^
sqlite3.OperationalError: no such column: Authentication_user.reminder_sent

The above exception was the direct cause of the following exception:

Traceback (most recent call last):
  File "/Users/vaibhavsingh/Desktop/ASMP25-26/Backend/venv/lib/python3.13/site-packages/django/core/handlers/exception.py", line 55, in inner
    response = get_response(request)
  File "/Users/vaibhavsingh/Desktop/ASMP25-26/Backend/venv/lib/python3.13/site-packages/django/core/handlers/base.py", line 197, in _get_response
    response = wrapped_callback(request, *callback_args, **callback_kwargs)
  File "/Users/vaibhavsingh/Desktop/ASMP25-26/Backend/venv/lib/python3.13/site-packages/django/views/decorators/csrf.py", line 65, in _view_wrapper
    return view_func(request, *args, **kwargs)
  File "/Users/vaibhavsingh/Desktop/ASMP25-26/Backend/venv/lib/python3.13/site-packages/django/views/generic/base.py", line 105, in view
    return self.dispatch(request, *args, **kwargs)
           ~~~~~~~~~~~~~^^^^^^^^^^^^^^^^^^^^^^^^^^
  File "/Users/vaibhavsingh/Desktop/ASMP25-26/Backend/venv/lib/python3.13/site-packages/rest_framework/views.py", line 515, in dispatch
    response = self.handle_exception(exc)
  File "/Users/vaibhavsingh/Desktop/ASMP25-26/Backend/venv/lib/python3.13/site-packages/rest_framework/views.py", line 475, in handle_exception
    self.raise_uncaught_exception(exc)
    ~~~~~~~~~~~~~~~~~~~~~~~~~~~~~^^^^^
  File "/Users/vaibhavsingh/Desktop/ASMP25-26/Backend/venv/lib/python3.13/site-packages/rest_framework/views.py", line 486, in raise_uncaught_exception
    raise exc
  File "/Users/vaibhavsingh/Desktop/ASMP25-26/Backend/venv/lib/python3.13/site-packages/rest_framework/views.py", line 512, in dispatch
    response = handler(request, *args, **kwargs)
  File "/Users/vaibhavsingh/Desktop/ASMP25-26/Backend/Registrations/views.py", line 184, in get
    user = User.objects.get(accessToken=accessToken)
  File "/Users/vaibhavsingh/Desktop/ASMP25-26/Backend/venv/lib/python3.13/site-packages/django/db/models/manager.py", line 87, in manager_method
    return getattr(self.get_queryset(), name)(*args, **kwargs)
           ~~~~~~~~~~~~~~~~~~~~~~~~~~~~~~~~~~^^^^^^^^^^^^^^^^^
  File "/Users/vaibhavsingh/Desktop/ASMP25-26/Backend/venv/lib/python3.13/site-packages/django/db/models/query.py", line 629, in get
    num = len(clone)
  File "/Users/vaibhavsingh/Desktop/ASMP25-26/Backend/venv/lib/python3.13/site-packages/django/db/models/query.py", line 366, in __len__
    self._fetch_all()
    ~~~~~~~~~~~~~~~^^
  File "/Users/vaibhavsingh/Desktop/ASMP25-26/Backend/venv/lib/python3.13/site-packages/django/db/models/query.py", line 1949, in _fetch_all
    self._result_cache = list(self._iterable_class(self))
                         ~~~~^^^^^^^^^^^^^^^^^^^^^^^^^^^^
  File "/Users/vaibhavsingh/Desktop/ASMP25-26/Backend/venv/lib/python3.13/site-packages/django/db/models/query.py", line 91, in __iter__
    results = compiler.execute_sql(
        chunked_fetch=self.chunked_fetch, chunk_size=self.chunk_size
    )
  File "/Users/vaibhavsingh/Desktop/ASMP25-26/Backend/venv/lib/python3.13/site-packages/django/db/models/sql/compiler.py", line 1623, in execute_sql
    cursor.execute(sql, params)
    ~~~~~~~~~~~~~~^^^^^^^^^^^^^
  File "/Users/vaibhavsingh/Desktop/ASMP25-26/Backend/venv/lib/python3.13/site-packages/django/db/backends/utils.py", line 122, in execute
    return super().execute(sql, params)
           ~~~~~~~~~~~~~~~^^^^^^^^^^^^^
  File "/Users/vaibhavsingh/Desktop/ASMP25-26/Backend/venv/lib/python3.13/site-packages/django/db/backends/utils.py", line 79, in execute
    return self._execute_with_wrappers(
           ~~~~~~~~~~~~~~~~~~~~~~~~~~~^
        sql, params, many=False, executor=self._execute
        ^^^^^^^^^^^^^^^^^^^^^^^^^^^^^^^^^^^^^^^^^^^^^^^
    )
    ^
  File "/Users/vaibhavsingh/Desktop/ASMP25-26/Backend/venv/lib/python3.13/site-packages/django/db/backends/utils.py", line 92, in _execute_with_wrappers
    return executor(sql, params, many, context)
  File "/Users/vaibhavsingh/Desktop/ASMP25-26/Backend/venv/lib/python3.13/site-packages/django/db/backends/utils.py", line 100, in _execute
    with self.db.wrap_database_errors:
         ^^^^^^^^^^^^^^^^^^^^^^^^^^^^
  File "/Users/vaibhavsingh/Desktop/ASMP25-26/Backend/venv/lib/python3.13/site-packages/django/db/utils.py", line 91, in __exit__
    raise dj_exc_value.with_traceback(traceback) from exc_value
  File "/Users/vaibhavsingh/Desktop/ASMP25-26/Backend/venv/lib/python3.13/site-packages/django/db/backends/utils.py", line 105, in _execute
    return self.cursor.execute(sql, params)
           ~~~~~~~~~~~~~~~~~~~^^^^^^^^^^^^^
  File "/Users/vaibhavsingh/Desktop/ASMP25-26/Backend/venv/lib/python3.13/site-packages/django/db/backends/sqlite3/base.py", line 360, in execute
    return super().execute(query, params)
           ~~~~~~~~~~~~~~~^^^^^^^^^^^^^^^
django.db.utils.OperationalError: no such column: Authentication_user.reminder_sent
/Users/vaibhavsingh/Desktop/ASMP25-26/Backend/Authentication/models.py changed, reloading.
Watching for file changes with StatReloader
Watching for file changes with StatReloader
